Workbook

Sheet Launch_Tracker
A1: Product_ID | B1: Product_Name | C1: Category | D1: Launch_Date | E1: Region | F1: Approval_Status | G1: Artwork_Status | H1: Launch_Status | I1: Launch_Blocker | J1: Blocker_Reason
A2: RPGGEN-001 | B2: Generic Product 1 | C2: Diabetes | D2: 46283 | E2: North | F2: Pending | G2: Draft | H2: Planned | I2: =IF(AND(F2="Approved",G2="Approved"),"Ready","Blocked") -> Blocked | J2: =IF(AND(F2="Approved",G2="Approved"),"Ready", IF(AND(F2<>"Approved",G2="Approved"),"Regulatory Delay", IF(AND(F2="Approved",G2<>"Approved"),"Artwork Delay","Multiple Issues"))) -> Multiple Issues
A3: RPGGEN-002 | B3: Generic Product 2 | C3: Diabetes | D3: 46204 | E3: East | F3: Pending | G3: Review | H3: Planned | I3: =IF(AND(F3="Approved",G3="Approved"),"Ready","Blocked") -> Blocked | J3: =IF(AND(F3="Approved",G3="Approved"),"Ready", IF(AND(F3<>"Approved",G3="Approved"),"Regulatory Delay", IF(AND(F3="Approved",G3<>"Approved"),"Artwork Delay","Multiple Issues"))) -> Multiple Issues
A4: RPGGEN-003 | B4: Generic Product 3 | C4: Diabetes | D4: 46253 | E4: West | F4: Approved | G4: Approved | H4: Launched | I4: =IF(AND(F4="Approved",G4="Approved"),"Ready","Blocked") -> Ready | J4: =IF(AND(F4="Approved",G4="Approved"),"Ready", IF(AND(F4<>"Approved",G4="Approved"),"Regulatory Delay", IF(AND(F4="Approved",G4<>"Approved"),"Artwork Delay","Multiple Issues"))) -> Ready
A5: RPGGEN-004 | B5: Generic Product 4 | C5: Cardio | D5: 46213 | E5: East | F5: Pending | G5: Draft | H5: In Progress | I5: =IF(AND(F5="Approved",G5="Approved"),"Ready","Blocked") -> Blocked | J5: =IF(AND(F5="Approved",G5="Approved"),"Ready", IF(AND(F5<>"Approved",G5="Approved"),"Regulatory Delay", IF(AND(F5="Approved",G5<>"Approved"),"Artwork Delay","Multiple Issues"))) -> Multiple Issues
A6: RPGGEN-005 | B6: Generic Product 5 | C6: Respiratory | D6: 46151 | E6: South | F6: Under Review | G6: Approved | H6: Planned | I6: =IF(AND(F6="Approved",G6="Approved"),"Ready","Blocked") -> Blocked | J6: =IF(AND(F6="Approved",G6="Approved"),"Ready", IF(AND(F6<>"Approved",G6="Approved"),"Regulatory Delay", IF(AND(F6="Approved",G6<>"Approved"),"Artwork Delay","Multiple Issues"))) -> Regulatory Delay
A7: RPGGEN-006 | B7: Generic Product 6 | C7: Oncology | D7: 46244 | E7: West | F7: Approved | G7: Approved | H7: Launched | I7: =IF(AND(F7="Approved",G7="Approved"),"Ready","Blocked") -> Ready | J7: =IF(AND(F7="Approved",G7="Approved"),"Ready", IF(AND(F7<>"Approved",G7="Approved"),"Regulatory Delay", IF(AND(F7="Approved",G7<>"Approved"),"Artwork Delay","Multiple Issues"))) -> Ready
A8: RPGGEN-007 | B8: Generic Product 7 | C8: Gastro | D8: 46038 | E8: East | F8: Under Review | G8: Approved | H8: Planned | I8: =IF(AND(F8="Approved",G8="Approved"),"Ready","Blocked") -> Blocked | J8: =IF(AND(F8="Approved",G8="Approved"),"Ready", IF(AND(F8<>"Approved",G8="Approved"),"Regulatory Delay", IF(AND(F8="Approved",G8<>"Approved"),"Artwork Delay","Multiple Issues"))) -> Regulatory Delay
A9: RPGGEN-008 | B9: Generic Product 8 | C9: Respiratory | D9: 46073 | E9: North | F9: Approved | G9: Draft | H9: Planned | I9: =IF(AND(F9="Approved",G9="Approved"),"Ready","Blocked") -> Blocked | J9: =IF(AND(F9="Approved",G9="Approved"),"Ready", IF(AND(F9<>"Approved",G9="Approved"),"Regulatory Delay", IF(AND(F9="Approved",G9<>"Approved"),"Artwork Delay","Multiple Issues"))) -> Artwork Delay
A10: RPGGEN-009 | B10: Generic Product 9 | C10: Oncology | D10: 46068 | E10: West | F10: Pending | G10: Approved | H10: In Progress | I10: =IF(AND(F10="Approved",G10="Approved"),"Ready","Blocked") -> Blocked | J10: =IF(AND(F10="Approved",G10="Approved"),"Ready", IF(AND(F10<>"Approved",G10="Approved"),"Regulatory Delay", IF(AND(F10="Approved",G10<>"Approved"),"Artwork Delay","Multiple Issues"))) -> Regulatory Delay
A11: RPGGEN-010 | B11: Generic Product 10 | C11: Respiratory | D11: 46208 | E11: South | F11: Under Review | G11: Draft | H11: Planned | I11: =IF(AND(F11="Approved",G11="Approved"),"Ready","Blocked") -> Blocked | J11: =IF(AND(F11="Approved",G11="Approved"),"Ready", IF(AND(F11<>"Approved",G11="Approved"),"Regulatory Delay", IF(AND(F11="Approved",G11<>"Approved"),"Artwork Delay","Multiple Issues"))) -> Multiple Issues
A12: RPGGEN-011 | B12: Generic Product 11 | C12: Diabetes | D12: 46217 | E12: South | F12: Pending | G12: Approved | H12: Launched | I12: =IF(AND(F12="Approved",G12="Approved"),"Ready","Blocked") -> Blocked | J12: =IF(AND(F12="Approved",G12="Approved"),"Ready", IF(AND(F12<>"Approved",G12="Approved"),"Regulatory Delay", IF(AND(F12="Approved",G12<>"Approved"),"Artwork Delay","Multiple Issues"))) -> Regulatory Delay
A13: RPGGEN-012 | B13: Generic Product 12 | C13: Oncology | D13: 46319 | E13: East | F13: Under Review | G13: Draft | H13: Planned | I13: =IF(AND(F13="Approved",G13="Approved"),"Ready","Blocked") -> Blocked | J13: =IF(AND(F13="Approved",G13="Approved"),"Ready", IF(AND(F13<>"Approved",G13="Approved"),"Regulatory Delay", IF(AND(F13="Approved",G13<>"Approved"),"Artwork Delay","Multiple Issues"))) -> Multiple Issues
... A51: RPGGEN-050 | B51: Generic Product 50 | C51: Gastro | D51: 46067 | E51: East | F51: Pending | G51: Review | H51: In Progress | I51: =IF(AND(F51="Approved",G51="Approved"),"Ready","Blocked") -> Blocked | J51: =IF(AND(F51="Approved",G51="Approved"),"Ready", IF(AND(F51<>"Approved",G51="Approved"),"Regulatory Delay", IF(AND(F51="Approved",G51<>"Approved"),"Artwork Delay","Multiple Issues"))) -> Multiple Issues

Sheet Weekly Launch Report
B2: 4th Week Launch Report
B4: Approval_Status | C4: Count | E4: Artwork_Status | F4: Count | H4: Launch_Status | I4: Count
B5: Pending | C5: =COUNTIF(Launch_Tracker!F:F,Launch_Tracker!F2) -> 17 | E5: Draft | F5: =COUNTIF(Table1[Artwork_Status],Launch_Tracker!G34) -> 16 | H5: Launched | I5: =COUNTIF(Launch_Tracker!H:H,"Launched") -> 13
B6: Under Review | C6: =COUNTIF(Launch_Tracker!F:F,Launch_Tracker!F3) -> 17 | E6: Review | F6: =COUNTIF(Table1[Artwork_Status],Launch_Tracker!G37) -> 16 | H6: Inprogress | I6: =COUNTIF(Launch_Tracker!$H:H,"In Progress") -> 19
B7: Approved | C7: =COUNTIF(Launch_Tracker!F:F,Launch_Tracker!F7) -> 13 | E7: Approved | F7: =COUNTIF(Table1[Artwork_Status],Launch_Tracker!G36) -> 14 | H7: Planned | I7: =COUNTIF(Launch_Tracker!$H:H,"Planned") -> 18
B8: SUM | C8: =SUM(C5:C7) -> 47 | E8: SUM | F8: =SUM(F5:F7) -> 46 | H8: SUM | I8: =SUM(I5:I7) -> 50
B11: Product_ID | C11: Approval pending | E11: Product_ID | F11: Artwork in draft | H11: Readiness to Launch
B12: RPGGEN-001 | C12: Generic Product 1 | E12: RPGGEN-001 | F12: Generic Product 1 | H12: Row Labels | I12: Count of Product_ID
B13: RPGGEN-002 | C13: Generic Product 2 | E13: RPGGEN-004 | F13: Generic Product 4 | H13: Ready | I13: 5
B14: RPGGEN-004 | C14: Generic Product 4 | E14: RPGGEN-008 | F14: Generic Product 8 | H14: Blocked | I14: 45
B15: RPGGEN-009 | C15: Generic Product 9 | E15: RPGGEN-010 | F15: Generic Product 10 | H15: Grand Total | I15: 50
B16: RPGGEN-011 | C16: Generic Product 11 | E16: RPGGEN-012 | F16: Generic Product 12
B17: RPGGEN-017 | C17: Generic Product 17 | E17: RPGGEN-013 | F17: Generic Product 13
B18: RPGGEN-018 | C18: Generic Product 18 | E18: RPGGEN-014 | F18: Generic Product 14 | H18: Product_ID | I18: Launch Ready
B19: RPGGEN-020 | C19: Generic Product 20 | E19: RPGGEN-015 | F19: Generic Product 15 | H19: RPGGEN-037 | I19: Generic Product 37
B20: RPGGEN-022 | C20: Generic Product 22 | E20: RPGGEN-019 | F20: Generic Product 19
B21: RPGGEN-030 | C21: Generic Product 30 | E21: RPGGEN-022 | F21: Generic Product 22
B22: RPGGEN-031 | C22: Generic Product 31 | E22: RPGGEN-028 | F22: Generic Product 28 | H22: Reason for Delay
B23: RPGGEN-034 | C23: Generic Product 34 | E23: RPGGEN-031 | F23: Generic Product 31 | H23: Row Labels | I23: Count of Product_ID
B24: RPGGEN-038 | C24: Generic Product 38 | E24: RPGGEN-032 | F24: Generic Product 32 | H24: Multiple Issues | I24: 22
B25: RPGGEN-039 | C25: Generic Product 39 | E25: RPGGEN-033 | F25: Generic Product 33 | H25: Regulatory Delay | I25: 15
B26: RPGGEN-041 | C26: Generic Product 41 | E26: RPGGEN-036 | F26: Generic Product 36 | H26: Artwork Delay | I26: 8
B27: RPGGEN-046 | C27: Generic Product 46 | E27: RPGGEN-045 | F27: Generic Product 45 | H27: Ready | I27: 5
B28: RPGGEN-050 | C28: Generic Product 50 | H28: Grand Total | I28: 50
B30: Total | C30: =COUNTIF(C12:C28,"Generic*") -> 17 | E30: Total | F30: =COUNTIF(F12:F27,"Generic*") -> 16

Sheet Sales_Data
A1: Month | B1: Month Name | C1: Product_ID | D1: Region | E1: Units_Sold | F1: Revenue_INR
A2: 1 | B2: =CHOOSE(Table2[[#This Row],[Month]], "Jan","Feb","Mar","Apr","May","Jun","Jul","Aug","Sep","Oct","Nov","Dec") -> Jan | C2: RPGGEN-001 | D2: South | E2: 2269 | F2: 272280
A3: 1 | B3: =CHOOSE(Table2[[#This Row],[Month]], "Jan","Feb","Mar","Apr","May","Jun","Jul","Aug","Sep","Oct","Nov","Dec") -> Jan | C3: RPGGEN-002 | D3: North | E3: 4140 | F3: 107640
A4: 1 | B4: =CHOOSE(Table2[[#This Row],[Month]], "Jan","Feb","Mar","Apr","May","Jun","Jul","Aug","Sep","Oct","Nov","Dec") -> Jan | C4: RPGGEN-003 | D4: North | E4: 1402 | F4: 162632
A5: 1 | B5: =CHOOSE(Table2[[#This Row],[Month]], "Jan","Feb","Mar","Apr","May","Jun","Jul","Aug","Sep","Oct","Nov","Dec") -> Jan | C5: RPGGEN-004 | D5: North | E5: 4455 | F5: 182655
A6: 1 | B6: =CHOOSE(Table2[[#This Row],[Month]], "Jan","Feb","Mar","Apr","May","Jun","Jul","Aug","Sep","Oct","Nov","Dec") -> Jan | C6: RPGGEN-005 | D6: South | E6: 4819 | F6: 395158
A7: 1 | B7: =CHOOSE(Table2[[#This Row],[Month]], "Jan","Feb","Mar","Apr","May","Jun","Jul","Aug","Sep","Oct","Nov","Dec") -> Jan | C7: RPGGEN-006 | D7: East | E7: 1115 | F7: 134915
A8: 1 | B8: =CHOOSE(Table2[[#This Row],[Month]], "Jan","Feb","Mar","Apr","May","Jun","Jul","Aug","Sep","Oct","Nov","Dec") -> Jan | C8: RPGGEN-007 | D8: South | E8: 1832 | F8: 214344
A9: 1 | B9: =CHOOSE(Table2[[#This Row],[Month]], "Jan","Feb","Mar","Apr","May","Jun","Jul","Aug","Sep","Oct","Nov","Dec") -> Jan | C9: RPGGEN-008 | D9: North | E9: 683 | F9: 17758
A10: 1 | B10: =CHOOSE(Table2[[#This Row],[Month]], "Jan","Feb","Mar","Apr","May","Jun","Jul","Aug","Sep","Oct","Nov","Dec") -> Jan | C10: RPGGEN-009 | D10: North | E10: 2459 | F10: 228687
A11: 1 | B11: =CHOOSE(Table2[[#This Row],[Month]], "Jan","Feb","Mar","Apr","May","Jun","Jul","Aug","Sep","Oct","Nov","Dec") -> Jan | C11: RPGGEN-010 | D11: East | E11: 3152 | F11: 438128
A12: 1 | B12: =CHOOSE(Table2[[#This Row],[Month]], "Jan","Feb","Mar","Apr","May","Jun","Jul","Aug","Sep","Oct","Nov","Dec") -> Jan | C12: RPGGEN-011 | D12: South | E12: 4552 | F12: 559896
A13: 1 | B13: =CHOOSE(Table2[[#This Row],[Month]], "Jan","Feb","Mar","Apr","May","Jun","Jul","Aug","Sep","Oct","Nov","Dec") -> Jan | C13: RPGGEN-012 | D13: South | E13: 1534 | F13: 179478
... A601: 12 | B601: =CHOOSE(Table2[[#This Row],[Month]], "Jan","Feb","Mar","Apr","May","Jun","Jul","Aug","Sep","Oct","Nov","Dec") -> Dec | C601: RPGGEN-050 | D601: East | E601: 4361 | F601: 575652

Sheet Sales Tracker
C2: Sales Tracker
C5: Region | D5: Sum of Revenue_INR | F5: Sum of Revenue_INR | G5: Region | L5: Contributon to Total Revenue
C6: East | D6: 34386026 | F6: Product ID | G6: East | H6: North | I6: South | J6: West | K6: Grand Total
C7: West | D7: 32433680 | F7: RPGGEN-011 | G7: 1135553 | H7: 46795 | I7: 1337631 | J7: 1714185 | K7: 4234164 | L7: =K7/125125944 -> 0.033839217
C8: South | D8: 31708927 | F8: RPGGEN-049 | G8: 658752 | H8: 795218 | I8: 1758110 | J8: 962136 | K8: 4174216 | L8: =K8/125125944 -> 0.033360116
C9: North | D9: 26597311 | F9: RPGGEN-004 | G9: 174900 | H9: 693359 | I9: 1219268 | J9: 1557392 | K9: 3644919 | L9: =K9/125125944 -> 0.029130002
C10: Grand Total | D10: 125125944 | F10: RPGGEN-046 | G10: 187560 | H10: 1863293 | I10: 659670 | J10: 878964 | K10: 3589487 | L10: =K10/125125944 -> 0.028686992
F11: RPGGEN-025 | G11: 533716 | H11: 627978 | I11: 472179 | J11: 1656832 | K11: 3290705 | L11: =K11/125125944 -> 0.026299142
F12: RPGGEN-009 | G12: 757493 | H12: 684437 | J12: 1793510 | K12: 3235440 | L12: =K12/125125944 -> 0.025857467
F13: RPGGEN-050 | G13: 1259337 | H13: 736955 | I13: 548887 | J13: 650685 | K13: 3195864 | L13: =K13/125125944 -> 0.025541178
F14: RPGGEN-022 | G14: 1244733 | H14: 717931 | I14: 780774 | J14: 395637 | K14: 3139075 | L14: =K14/125125944 -> 0.025087323
F15: RPGGEN-010 | G15: 1610859 | H15: 418950 | I15: 438721 | J15: 507277 | K15: 2975807 | L15: =K15/125125944 -> 0.023782494
F16: RPGGEN-026 | G16: 1546839 | H16: 1004467 | I16: 338436 | J16: 84634 | K16: 2974376 | L16: =K16/125125944 -> 0.023771057
F17: RPGGEN-001 | G17: 841561 | H17: 975305 | I17: 502187 | J17: 637166 | K17: 2956219 | L17: =K17/125125944 -> 0.023625948
F18: RPGGEN-045 | G18: 1016886 | H18: 867668 | I18: 1054135 | K18: 2938689 | L18: =K18/125125944 -> 0.023485849
F19: RPGGEN-048 | G19: 1348744 | H19: 333080 | I19: 1013596 | J19: 170002 | K19: 2865422 | L19: =K19/125125944 -> 0.022900303
F20: RPGGEN-024 | G20: 1693624 | I20: 829671 | J20: 340108 | K20: 2863403 | L20: =K20/125125944 -> 0.022884167
F21: RPGGEN-039 | G21: 860557 | H21: 770091 | I21: 223256 | J21: 967098 | K21: 2821002 | L21: =K21/125125944 -> 0.0225453
F22: RPGGEN-003 | G22: 264480 | H22: 323357 | I22: 785669 | J22: 1420177 | K22: 2793683 | L22: =K22/125125944 -> 0.022326968
F23: RPGGEN-034 | G23: 554708 | H23: 365282 | I23: 324707 | J23: 1502402 | K23: 2747099 | L23: =K23/125125944 -> 0.021954672
F24: RPGGEN-042 | G24: 1964589 | H24: 306792 | I24: 459962 | K24: 2731343 | L24: =K24/125125944 -> 0.02182875
F25: RPGGEN-027 | G25: 373345 | H25: 862786 | I25: 348907 | J25: 1145492 | K25: 2730530 | L25: =K25/125125944 -> 0.021822253
F26: RPGGEN-015 | G26: 997971 | H26: 199355 | I26: 1014106 | J26: 490192 | K26: 2701624 | L26: =K26/125125944 -> 0.021591238
C27: Month | D27: Sum of Revenue_INR | F27: RPGGEN-018 | G27: 468851 | H27: 1203739 | I27: 197630 | J27: 687581 | K27: 2557801 | L27: =K27/125125944 -> 0.020441812
C28: Jan | D28: 11523638 | F28: RPGGEN-005 | G28: 332151 | H28: 126392 | I28: 407368 | J28: 1668459 | K28: 2534370 | L28: =K28/125125944 -> 0.020254552
C29: Feb | D29: 10009608 | F29: RPGGEN-041 | G29: 54211 | H29: 259366 | I29: 800924 | J29: 1395233 | K29: 2509734 | L29: =K29/125125944 -> 0.020057663
C30: Mar | D30: 10425350 | F30: RPGGEN-028 | G30: 561044 | H30: 1068510 | I30: 256536 | J30: 610440 | K30: 2496530 | L30: =K30/125125944 -> 0.019952137
C31: Apr | D31: 9958906 | F31: RPGGEN-012 | G31: 586680 | H31: 516475 | I31: 819268 | J31: 559499 | K31: 2481922 | L31: =K31/125125944 -> 0.019835391
C32: May | D32: 11306658 | F32: RPGGEN-043 | G32: 319580 | H32: 1414933 | I32: 140474 | J32: 588344 | K32: 2463331 | L32: =K32/125125944 -> 0.019686813
C33: Jun | D33: 10896250 | F33: RPGGEN-029 | G33: 485184 | H33: 298221 | I33: 920720 | J33: 756431 | K33: 2460556 | L33: =K33/125125944 -> 0.019664635
C34: Jul | D34: 9618402 | F34: RPGGEN-032 | G34: 168586 | H34: 658480 | I34: 466893 | J34: 1137431 | K34: 2431390 | L34: =K34/125125944 -> 0.019431542
C35: Aug | D35: 10361972 | F35: RPGGEN-017 | G35: 667870 | H35: 452005 | I35: 491508 | J35: 786250 | K35: 2397633 | L35: =K35/125125944 -> 0.019161758
C36: Sep | D36: 10595538 | F36: RPGGEN-002 | G36: 535814 | H36: 525692 | I36: 535291 | J36: 736648 | K36: 2333445 | L36: =K36/125125944 -> 0.01864877
C37: Oct | D37: 10984339 | F37: RPGGEN-023 | G37: 708044 | H37: 566042 | I37: 704741 | J37: 245538 | K37: 2224365 | L37: =K37/125125944 -> 0.017777009
C38: Nov | D38: 9989880 | F38: RPGGEN-031 | G38: 531987 | H38: 292066 | I38: 952965 | J38: 432027 | K38: 2209045 | L38: =K38/125125944 -> 0.017654572
C39: Dec | D39: 9455403 | F39: RPGGEN-033 | G39: 1243560 | H39: 231550 | I39: 487910 | J39: 231670 | K39: 2194690 | L39: =K39/125125944 -> 0.017539848
C40: Grand Total | D40: 125125944 | F40: RPGGEN-021 | G40: 1036735 | H40: 417057 | I40: 657599 | J40: 18167 | K40: 2129558 | L40: =K40/125125944 -> 0.017019316
F41: RPGGEN-014 | G41: 900068 | H41: 264286 | I41: 330541 | J41: 608691 | K41: 2103586 | L41: =K41/125125944 -> 0.016811749
F42: RPGGEN-006 | G42: 473499 | H42: 266928 | I42: 1319518 | J42: 26341 | K42: 2086286 | L42: =K42/125125944 -> 0.016673489
F43: RPGGEN-030 | G43: 604233 | H43: 763944 | I43: 336140 | J43: 340462 | K43: 2044779 | L43: =K43/125125944 -> 0.016341767
...

Sheet Inventory
A1: Product_ID | B1: Opening_Stock | C1: Current_Stock | D1: Weekly_Demand | E1: Lead_Time_Days | F1: Safety_Stock | G1: Reorder_Point | H1: Reorder_Status
A2: RPGGEN-001 | B2: 5938 | C2: 810 | D2: 461 | E2: 16 | F2: 922 | G2: 1844 | H2: =IF(Table3[[#This Row],[Current_Stock]]<=Table3[[#This Row],[Reorder_Point]],"Reorder Required","Stock Sufficient") -> Reorder Required
A3: RPGGEN-002 | B3: 3812 | C3: 3374 | D3: 116 | E3: 16 | F3: 232 | G3: 464 | H3: =IF(Table3[[#This Row],[Current_Stock]]<=Table3[[#This Row],[Reorder_Point]],"Reorder Required","Stock Sufficient") -> Stock Sufficient
A4: RPGGEN-003 | B4: 6121 | C4: 996 | D4: 258 | E4: 23 | F4: 516 | G4: 1290 | H4: =IF(Table3[[#This Row],[Current_Stock]]<=Table3[[#This Row],[Reorder_Point]],"Reorder Required","Stock Sufficient") -> Reorder Required
A5: RPGGEN-004 | B5: 4301 | C5: 1955 | D5: 113 | E5: 14 | F5: 226 | G5: 452 | H5: =IF(Table3[[#This Row],[Current_Stock]]<=Table3[[#This Row],[Reorder_Point]],"Reorder Required","Stock Sufficient") -> Stock Sufficient
A6: RPGGEN-005 | B6: 4938 | C6: 2960 | D6: 478 | E6: 30 | F6: 956 | G6: 2868 | H6: =IF(Table3[[#This Row],[Current_Stock]]<=Table3[[#This Row],[Reorder_Point]],"Reorder Required","Stock Sufficient") -> Stock Sufficient
A7: RPGGEN-006 | B7: 7923 | C7: 1773 | D7: 275 | E7: 21 | F7: 550 | G7: 1375 | H7: =IF(Table3[[#This Row],[Current_Stock]]<=Table3[[#This Row],[Reorder_Point]],"Reorder Required","Stock Sufficient") -> Stock Sufficient
A8: RPGGEN-007 | B8: 3488 | C8: 4656 | D8: 221 | E8: 15 | F8: 442 | G8: 884 | H8: =IF(Table3[[#This Row],[Current_Stock]]<=Table3[[#This Row],[Reorder_Point]],"Reorder Required","Stock Sufficient") -> Stock Sufficient
A9: RPGGEN-008 | B9: 3223 | C9: 1485 | D9: 472 | E9: 21 | F9: 944 | G9: 2360 | H9: =IF(Table3[[#This Row],[Current_Stock]]<=Table3[[#This Row],[Reorder_Point]],"Reorder Required","Stock Sufficient") -> Reorder Required
A10: RPGGEN-009 | B10: 7758 | C10: 3389 | D10: 125 | E10: 12 | F10: 250 | G10: 375 | H10: =IF(Table3[[#This Row],[Current_Stock]]<=Table3[[#This Row],[Reorder_Point]],"Reorder Required","Stock Sufficient") -> Stock Sufficient
A11: RPGGEN-010 | B11: 5739 | C11: 4527 | D11: 214 | E11: 28 | F11: 428 | G11: 1284 | H11: =IF(Table3[[#This Row],[Current_Stock]]<=Table3[[#This Row],[Reorder_Point]],"Reorder Required","Stock Sufficient") -> Stock Sufficient
A12: RPGGEN-011 | B12: 4609 | C12: 2310 | D12: 500 | E12: 16 | F12: 1000 | G12: 2000 | H12: =IF(Table3[[#This Row],[Current_Stock]]<=Table3[[#This Row],[Reorder_Point]],"Reorder Required","Stock Sufficient") -> Stock Sufficient
A13: RPGGEN-012 | B13: 3836 | C13: 1700 | D13: 145 | E13: 15 | F13: 290 | G13: 580 | H13: =IF(Table3[[#This Row],[Current_Stock]]<=Table3[[#This Row],[Reorder_Point]],"Reorder Required","Stock Sufficient") -> Stock Sufficient
... A51: RPGGEN-050 | B51: 6785 | C51: 3594 | D51: 291 | E51: 29 | F51: 582 | G51: 1746 | H51: =IF(Table3[[#This Row],[Current_Stock]]<=Table3[[#This Row],[Reorder_Point]],"Reorder Required","Stock Sufficient") -> Stock Sufficient

Sheet Reorder Plan
B4: Row Labels | C4: Count of Product_ID | E4: Products need to be Reordered | F4: Product_ID
B5: Reorder Required | C5: 12 | F5: RPGGEN-001
B6: Stock Sufficient | C6: 38 | F6: RPGGEN-003
B7: Grand Total | C7: 50 | F7: RPGGEN-008
F8: RPGGEN-016
F9: RPGGEN-021
F10: RPGGEN-028
F11: RPGGEN-029
F12: RPGGEN-037
F13: RPGGEN-044
F14: RPGGEN-045
F15: RPGGEN-048
F16: RPGGEN-049

Sheet Artwork_Pipeline
A1: Product_ID | B1: Artwork_Submission | C1: Review_Status | D1: Regulatory_Check | E1: Final_Signoff | F1: Stage
A2: RPGGEN-001 | B2: Submitted | C2: Changes Requested | D2: Approved | E2: Signed Off | F2: =IF(E2="Signed Off","Complete", IF(B2="Pending","Submission Pending", IF(C2="Changes Requested","Rework Required", IF(C2="In Review","Under Review", IF(D2="Pending","Regulatory Review", "Awaiting Final Sign-off"))))) -> Complete
A3: RPGGEN-002 | B3: Submitted | C3: In Review | D3: Pending | E3: Pending | F3: =IF(E3="Signed Off","Complete", IF(B3="Pending","Submission Pending", IF(C3="Changes Requested","Rework Required", IF(C3="In Review","Under Review", IF(D3="Pending","Regulatory Review", "Awaiting Final Sign-off"))))) -> Under Review
A4: RPGGEN-003 | B4: Submitted | C4: Changes Requested | D4: Pending | E4: Pending | F4: =IF(E4="Signed Off","Complete", IF(B4="Pending","Submission Pending", IF(C4="Changes Requested","Rework Required", IF(C4="In Review","Under Review", IF(D4="Pending","Regulatory Review", "Awaiting Final Sign-off"))))) -> Rework Required
A5: RPGGEN-004 | B5: Pending | C5: Changes Requested | D5: Approved | E5: Pending | F5: =IF(E5="Signed Off","Complete", IF(B5="Pending","Submission Pending", IF(C5="Changes Requested","Rework Required", IF(C5="In Review","Under Review", IF(D5="Pending","Regulatory Review", "Awaiting Final Sign-off"))))) -> Submission Pending
A6: RPGGEN-005 | B6: Submitted | C6: Changes Requested | D6: Approved | E6: Pending | F6: =IF(E6="Signed Off","Complete", IF(B6="Pending","Submission Pending", IF(C6="Changes Requested","Rework Required", IF(C6="In Review","Under Review", IF(D6="Pending","Regulatory Review", "Awaiting Final Sign-off"))))) -> Rework Required
A7: RPGGEN-006 | B7: Submitted | C7: In Review | D7: Pending | E7: Signed Off | F7: =IF(E7="Signed Off","Complete", IF(B7="Pending","Submission Pending", IF(C7="Changes Requested","Rework Required", IF(C7="In Review","Under Review", IF(D7="Pending","Regulatory Review", "Awaiting Final Sign-off"))))) -> Complete
A8: RPGGEN-007 | B8: Pending | C8: In Review | D8: Approved | E8: Pending | F8: =IF(E8="Signed Off","Complete", IF(B8="Pending","Submission Pending", IF(C8="Changes Requested","Rework Required", IF(C8="In Review","Under Review", IF(D8="Pending","Regulatory Review", "Awaiting Final Sign-off"))))) -> Submission Pending
A9: RPGGEN-008 | B9: Pending | C9: Changes Requested | D9: Pending | E9: Pending | F9: =IF(E9="Signed Off","Complete", IF(B9="Pending","Submission Pending", IF(C9="Changes Requested","Rework Required", IF(C9="In Review","Under Review", IF(D9="Pending","Regulatory Review", "Awaiting Final Sign-off"))))) -> Submission Pending
A10: RPGGEN-009 | B10: Submitted | C10: Approved | D10: Approved | E10: Pending | F10: =IF(E10="Signed Off","Complete", IF(B10="Pending","Submission Pending", IF(C10="Changes Requested","Rework Required", IF(C10="In Review","Under Review", IF(D10="Pending","Regulatory Review", "Awaiting Final Sign-off"))))) -> Awaiting Final Sign-off
A11: RPGGEN-010 | B11: Submitted | C11: In Review | D11: Approved | E11: Signed Off | F11: =IF(E11="Signed Off","Complete", IF(B11="Pending","Submission Pending", IF(C11="Changes Requested","Rework Required", IF(C11="In Review","Under Review", IF(D11="Pending","Regulatory Review", "Awaiting Final Sign-off"))))) -> Complete
A12: RPGGEN-011 | B12: Pending | C12: Approved | D12: Approved | E12: Pending | F12: =IF(E12="Signed Off","Complete", IF(B12="Pending","Submission Pending", IF(C12="Changes Requested","Rework Required", IF(C12="In Review","Under Review", IF(D12="Pending","Regulatory Review", "Awaiting Final Sign-off"))))) -> Submission Pending
A13: RPGGEN-012 | B13: Pending | C13: Approved | D13: Pending | E13: Pending | F13: =IF(E13="Signed Off","Complete", IF(B13="Pending","Submission Pending", IF(C13="Changes Requested","Rework Required", IF(C13="In Review","Under Review", IF(D13="Pending","Regulatory Review", "Awaiting Final Sign-off"))))) -> Submission Pending
... A51: RPGGEN-050 | B51: Submitted | C51: In Review | D51: Approved | E51: Pending | F51: =IF(E51="Signed Off","Complete", IF(B51="Pending","Submission Pending", IF(C51="Changes Requested","Rework Required", IF(C51="In Review","Under Review", IF(D51="Pending","Regulatory Review", "Awaiting Final Sign-off"))))) -> Under Review

Sheet Artwork Progress
B4: Artwork Stage | C4: Count of Product_ID
B5: Awaiting Final Sign-off | C5: 1
B6: Regulatory Review | C6: 2
B7: Under Review | C7: 6
B8: Rework Required | C8: 7
B9: Submission Pending | C9: 12
B10: Complete | C10: 22
B11: Grand Total | C11: 50

Sheet Executive Insights
A1: Executive Insights:
A4: 1. Only 5 of 50 products (10%) are launch-ready; 45 products remain blocked.
A5: 2. Multiple issues (22 products) are the leading cause of launch delays.
A6: 3. 17 products are pending approval, indicating a regulatory bottleneck.
A7: 4. 22 products have completed the artwork process, while 12 are awaiting submission.
A8: 5. 12 products require immediate reordering to avoid potential stock shortages.
A9: 6. East is the highest revenue-generating region, while North records the lowest revenue.
A10: 7. Monthly revenue remains relatively stable with moderate fluctuations.
A11: 8. Revenue is concentrated among a small number of high-performing products.
